<?xml version="1.0"?>
<robot xmlns:xacro="http://www.ros.org/wiki/xacro">

<xacro:macro name="end_effector" params="prefix">
  <link name="${prefix}end_effector">
    <inertial>
      <origin xyz="0.00052063255921888 0.000297558030083706 0.0577395076620412" rpy="0 0 0"/>
      <mass value="0.0268863153129509"/>
      <inertia ixx="7.16843100504782E-06" ixy="-2.16004182896192E-18" ixz="1.45205222495832E-17"
               iyy="5.41074299136263E-06" iyz="-6.95119128869655E-08" izz="1.95010952707155E-06"/>
    </inertial>
    <visual>
      <origin xyz="0 0 0" rpy="0 0 0"/>
      <geometry>
        <mesh filename="file://$(find mec_mobile_description)/meshes/robot_omni_3d/end_effector.STL"/>
      </geometry>
      <material name="gray"/>
    </visual>
    <collision>
      <origin xyz="0 0 0" rpy="0 0 0"/>
      <geometry>
        <mesh filename="file://$(find mec_mobile_description)/meshes/robot_omni_3d/end_effector.STL"/>
      </geometry>
    </collision>
  </link>

  <joint name="${prefix}end_effector_joint" type="revolute">
    <origin xyz="0.038628 0.0052916 0.019564" rpy="0 0 1.5708"/>
    <parent link="${prefix}Link_5"/>
    <child link="${prefix}end_effector"/>
    <axis xyz="0 0 1"/>
    <limit lower="-1.57" upper="0" effort="10" velocity="100"/>
  </joint>

  <gazebo reference="${prefix}end_effector">
    <material>Gazebo/gray</material>
  </gazebo>
</xacro:macro>

</robot>